[2025-10-27T08:56:41.032+0000] {local_task_job_runner.py:120} INFO - ::group::Pre task execution logs
[2025-10-27T08:56:41.079+0000] {taskinstance.py:2076} INFO - Dependencies all met for dep_context=non-requeueable deps ti=<TaskInstance: dataco_supply_chain_pipeline.ingest_csv manual__2025-10-27T08:56:38.780298+00:00 [queued]>
[2025-10-27T08:56:41.094+0000] {taskinstance.py:2076} INFO - Dependencies all met for dep_context=requeueable deps ti=<TaskInstance: dataco_supply_chain_pipeline.ingest_csv manual__2025-10-27T08:56:38.780298+00:00 [queued]>
[2025-10-27T08:56:41.095+0000] {taskinstance.py:2306} INFO - Starting attempt 1 of 1
[2025-10-27T08:56:41.118+0000] {taskinstance.py:2330} INFO - Executing <Task(PythonOperator): ingest_csv> on 2025-10-27 08:56:38.780298+00:00
[2025-10-27T08:56:41.126+0000] {standard_task_runner.py:64} INFO - Started process 323 to run task
[2025-10-27T08:56:41.128+0000] {standard_task_runner.py:90} INFO - Running: ['***', 'tasks', 'run', 'dataco_supply_chain_pipeline', 'ingest_csv', 'manual__2025-10-27T08:56:38.780298+00:00', '--job-id', '38', '--raw', '--subdir', 'DAGS_FOLDER/DataCo_pipeline_DAG.py', '--cfg-path', '/tmp/tmpxzji7dkd']
[2025-10-27T08:56:41.130+0000] {standard_task_runner.py:91} INFO - Job 38: Subtask ingest_csv
[2025-10-27T08:56:41.211+0000] {task_command.py:426} INFO - Running <TaskInstance: dataco_supply_chain_pipeline.ingest_csv manual__2025-10-27T08:56:38.780298+00:00 [running]> on host 787267c1a4b2
[2025-10-27T08:56:41.393+0000] {taskinstance.py:2648} INFO - Exporting env vars: AIRFLOW_CTX_DAG_EMAIL='bi@example.com' AIRFLOW_CTX_DAG_OWNER='DE-team' AIRFLOW_CTX_DAG_ID='dataco_supply_chain_pipeline' AIRFLOW_CTX_TASK_ID='ingest_csv' AIRFLOW_CTX_EXECUTION_DATE='2025-10-27T08:56:38.780298+00:00' AIRFLOW_CTX_TRY_NUMBER='1' AIRFLOW_CTX_DAG_RUN_ID='manual__2025-10-27T08:56:38.780298+00:00'
[2025-10-27T08:56:41.396+0000] {taskinstance.py:430} INFO - ::endgroup::
[2025-10-27T08:57:16.601+0000] {local_task_job_runner.py:313} WARNING - State of this instance has been externally set to failed. Terminating instance.
[2025-10-27T08:57:16.604+0000] {local_task_job_runner.py:222} INFO - ::endgroup::
[2025-10-27T08:57:16.606+0000] {process_utils.py:132} INFO - Sending 15 to group 323. PIDs of all processes in the group: [323]
[2025-10-27T08:57:16.607+0000] {process_utils.py:87} INFO - Sending the signal 15 to group 323
[2025-10-27T08:57:16.608+0000] {taskinstance.py:2611} ERROR - Received SIGTERM. Terminating subprocesses.
[2025-10-27T08:57:16.609+0000] {taskinstance.py:441} INFO - ::group::Post task execution logs
[2025-10-27T08:57:16.741+0000] {process_utils.py:80} INFO - Process psutil.Process(pid=323, status='terminated', exitcode=0) (323) terminated with exit code 0
